Workbook

Sheet Daily entry
A1: Date | B1: PoE | C1: Entry screened | D1: Exit screened | E1: Total screened (only if entry/exit not recorded) | F1: Alerts triggered | G1: Alerts closed (discarded or referred) | H1: Number of bodies moved across the border | I1: Notes
A2: 46295 | B2: Nimule | C2: 12269 | D2: 8969 | F2: 0 | G2: 0 | H2: 0
A3: 46295 | B3: Kaya | E3: 4435 | F3: 0 | G3: 0 | H3: 0
A4: 46295 | B4: Rei-river port | E4: 610 | F4: 0 | G4: 0 | H4: 0
A5: 46295 | B5: Olikwi | E5: 1326 | F5: 0 | G5: 0 | H5: 0
A6: 46296 | B6: Nimule | C6: 10425 | D6: 0 | F6: 0 | G6: 0 | H6: 0
A7: 46296 | B7: Kaya | E7: 2880 | F7: 0 | G7: 0 | H7: 0
A8: 46296 | B8: Rei-river port | E8: 555
A9: 46296 | B9: Olikwi | E9: 1345 | F9: 0 | G9: 0 | H9: 0
A10: 46297 | B10: Nimule | C10: 11583 | D10: 9708 | F10: 0 | G10: 0 | H10: 0
A11: 46297 | B11: Kaya | E11: 6820 | F11: 0 | G11: 0 | H11: 0
A12: 46297 | B12: Rei-river port | E12: 570 | F12: 0 | G12: 0 | H12: 0
A13: 46297 | B13: Olikwi | E13: 1178 | F13: 0 | G13: 0 | H13: 0
A14: 46298 | B14: Nimule | C14: 11358 | D14: 11106 | F14: 0 | G14: 0 | H14: 0
A15: 46298 | B15: Kaya | E15: 2695 | F15: 0 | G15: 0 | H15: 0
A16: 46298 | B16: Olikwi | E16: 1408 | F16: 0 | G16: 0 | H16: 0
A17: 46298 | B17: Rei-river port | E17: 545 | F17: 0 | G17: 0 | H17: 0
A18: 46299 | B18: Kaya | E18: 2880 | F18: 0 | G18: 0 | H18: 0
A19: 46299 | B19: Rei-river port | E19: 555 | F19: 0 | G19: 0 | H19: 0
A20: 46299 | B20: Olikwi | E20: 1345 | F20: 0 | G20: 0 | H20: 0
A21: 46299 | B21: Nimule | C21: 10425 | D21: 0 | F21: 0 | G21: 0 | H21: 0
A22: 46300 | B22: Nimule | C22: 11867 | D22: 0 | F22: 0 | G22: 0 | H22: 0
A23: 46300 | B23: Kaya | E23: 2318 | F23: 0 | G23: 0 | H23: 0
A24: 46300 | B24: Rei-river port | E24: 572 | F24: 0 | G24: 0 | H24: 0
A25: 46300 | B25: Olikwi | E25: 1375 | F25: 0 | G25: 0 | H25: 0
A26: 46301 | B26: Kaya | E26: 2830 | F26: 0 | G26: 0 | H26: 0
A27: 46301 | B27: Rei-river port | E27: 569 | F27: 0 | G27: 0 | H27: 0
A28: 46301 | B28: Olikwi | E28: 1185 | F28: 0 | G28: 0 | H28: 0
A29: 46301 | B29: Nimule | C29: 11867 | D29: 8173 | F29: 0 | G29: 0 | H29: 0
A30: 46302 | B30: Nimule | C30: 11378 | D30: 7670 | F30: 0 | G30: 0 | H30: 0
A31: 46302 | B31: Kaya | E31: 2830 | F31: 0 | G31: 0 | H31: 0
A32: 46302 | B32: Olikwi | E32: 1185 | F32: 0 | G32: 0 | H32: 0
A33: 46302 | B33: Rei-river port | E33: 569 | F33: 0 | G33: 0 | H33: 0
A34: 46303 | B34: Kaya | E34: 2540 | F34: 0 | G34: 0 | H34: 0
A35: 46303 | B35: Rei-river port | E35: 588 | F35: 0 | G35: 0 | H35: 0
A36: 46303 | B36: Olikwi | E36: 1305 | F36: 0 | G36: 0 | H36: 0
A37: 46303 | B37: Nimule | C37: 11792 | D37: 8178 | F37: 0 | G37: 0 | H37: 0

Sheet PoE List
A1: PoE | B1: border_country | C1: state | D1: county | E1: longitude | F1: latitude | G1: poe_type
A2: Nabanga | B2: DRC | C2: Western Equatoria | D2: Ibba | E2: 29.149029 | F2: 4.506468 | G2: Land
A3: Juba International Airport | B3: Inland | C3: Central Equatoria | D3: Juba | E3: 31.60179 | F3: 4.866439 | G3: Airport
A4: Litoba | B4: Uganda | C4: Central Equatoria | D4: Kajo-Keji | E4: 31.49 | F4: 3.89 | G4: Land
A5: Abaya | B5: Uganda | C5: Central Equatoria | D5: Kajo-Keji | E5: 31.666667 | F5: 3.884782 | G5: Land
A6: Jalle | B6: Uganda | C6: Central Equatoria | D6: Kajo-Keji | E6: 31.658617 | F6: 3.7233167 | G6: Land
A7: Kerwa | B7: Uganda | C7: Central Equatoria | D7: Kajo-Keji | E7: 31.310033 | F7: 3.7861167 | G7: Land
A8: Nimule | B8: Uganda | C8: Eastern Equatoria | D8: Magwi | E8: 32.067322 | F8: 3.58564 | G8: Land
A9: Rei-river port | B9: Uganda | C9: Eastern Equatoria | D9: Magwi | E9: 32.04394 | F9: 3.595669 | G9: River port
A10: Olikwi | B10: Uganda | C10: Eastern Equatoria | D10: Magwi | E10: 32.079162 | F10: 3.572004 | G10: Land
A11: Pogee | B11: Uganda | C11: Eastern Equatoria | D11: Magwi | E11: 32.51735 | F11: 3.7666 | G11: Land
A12: Lobone | B12: Uganda | C12: Eastern Equatoria | D12: Magwi | E12: 32.724818 | F12: 3.7932584 | G12: Land
A13: Rasul (Landili) | B13: DRC | C13: Western Equatoria | D13: Maridi | E13: 29.860761 | F13: 4.599492 | G13: Land
A14: Kaya | B14: DRC, Uganda | C14: Central Equatoria | D14: Morobo | E14: 30.93895 | F14: 3.785335 | G14: Land
A15: Saliamusala | B15: Uganda | C15: Central Equatoria | D15: Morobo | G15: Land
A16: Khor Kaya | B16: Uganda | C16: Central Equatoria | D16: Morobo | E16: 31.03555 | F16: 3.716567 | G16: Land
A17: Bazi | B17: DRC | C17: Central Equatoria | D17: Morobo | E17: 30.464753 | F17: 3.9466625 | G17: Land
A18: Ukaba/Okaba | B18: DRC | C18: Central Equatoria | D18: Morobo | G18: Land
A19: Sangua-1 | B19: DRC | C19: Western Equatoria | D19: Nzara | E19: 28.123727 | F19: 4.598792 | G19: Land
A20: South Yubu | B20: CAR | C20: Western Equatoria | D20: Tambura | E20: 27.495648 | F20: 5.6474633 | G20: Land
A21: Nangarangara | B21: CAR | C21: Western Equatoria | D21: Tambura | E21: 27.916308 | F21: 4.6848 | G21: Land
A22: Nabiapai-Yambio | B22: DRC | C22: Western Equatoria | D22: Yambio | E22: 28.568109 | F22: 4.3872262 | G22: Land
A23: Yambio Airport | B23: DRC | C23: Western Equatoria | D23: Yambio | E23: 28.424076 | F23: 4.567275 | G23: Land
A24: Sakure | B24: DRC | C24: Western Equatoria | D24: Yambio | E24: 28.211664 | F24: 4.39654 | G24: Land
A25: Ombasi | B25: DRC | C25: Central Equatoria | D25: Yei River | E25: 30.607598 | F25: 3.8870472 | G25: Land
A26: Minyori | B26: DRC | C26: Central Equatoria | D26: Yei River | E26: 30.619978 | F26: 4.1246651 | G26: Land
A27: Garamba | B27: DRC | C27: Central Equatoria | D27: Yei River | E27: 29.98 | F27: 4.62 | G27: Land
A28: Yei Airstrip | B28: DRC | C28: Central Equatoria | D28: Yei River | E28: 30.738224 | F28: 4.127487 | G28: Land
A29: Lasu | B29: DRC | C29: Central Equatoria | D29: Yei River | E29: 30.669155 | F29: 4.092169 | G29: Airstrip
A30: Libogo | B30: DRC | C30: Central Equatoria | D30: Yei River | E30: 30.593409 | F30: 3.822015 | G30: Land
A31: Bazikangbi | B31: DRC | C31: Western Equatoria | D31: Nzara | E31: 28.057625 | F31: 4.6851409 | G31: Land
A32: Nabiapai-Ezo | B32: DRC, CAR | C32: Western Equatoria | D32: Ezo | G32: Land
A33: Wau Airport | B33: Inland | C33: Western Bahr el Ghazal | D33: Wau | E33: 27.978839 | F33: 7.724798 | G33: Airport
A34: Sertenya | B34: Uganda | C34: Eastern Equatoria | D34: Ikwotos | E34: 33.15 | F34: 3.8833333 | G34: Land
A35: Bira | B35: Uganda | C35: Eastern Equatoria | D35: Ikwotos | E35: 33.573392 | F35: 3.8628126 | G35: Land
A36: Katire | B36: Uganda | C36: Eastern Equatoria | D36: Ikwotos | E36: 32.776535 | F36: 4.03643 | G36: Land
A37: Lofus | B37: Uganda | C37: Eastern Equatoria | D37: Ikwotos | E37: 33.196662 | F37: 3.8545968 | G37: Land
A38: Nadapal | B38: Kenya | C38: Eastern Equatoria | D38: Kapoeta South | E38: 33.84509 | F38: 5.16719 | G38: Land
A39: Torit Airstrip | B39: Inland | C39: Eastern Equatoria | D39: Torit | E39: 32.578861 | F39: 4.412156 | G39: Airstrip
A40: Budi Airstrip | B40: Inland | C40: Eastern Equatoria | D40: Budi | E40: 33.488704 | F40: 4.196277 | G40: Airstrip

Sheet Reporting check
A1: Reporting check – which PoEs have submitted each day
A2: First day shown: | B2: =TODAY()-14 -> 46293 | C2: (defaults to 14 days ago)
A4: PoE | B4: Days reported (of 14) | C4: Last report | D4: =$B$2+0 -> 46293 | E4: =$B$2+1 -> 46294 | F4: =$B$2+2 -> 46295 | G4: =$B$2+4 -> 46297 | H4: =$B$2+5 -> 46298 | I4: =$B$2+6 -> 46299 | J4: =$B$2+7 -> 46300 | K4: =$B$2+8 -> 46301 | L4: =$B$2+9 -> 46302 | M4: =$B$2+10 -> 46303 | N4: =$B$2+11 -> 46304 | O4: =$B$2+12 -> 46305 | P4: =$B$2+13 -> 46306 | Q4: =$B$2+14 -> 46307
A5: Nabanga | B5: =COUNTIF(D10:Q10,"✓") -> 0 | C5: =IF(COUNTIF('Daily entry'!$B$2:$B$3001,$A10)=0,"Never",_xlfn.MAXIFS('Daily entry'!$A$2:$A$3001,'Daily entry'!$B$2:$B$3001,$A10)) -> Never | D5: =IF(COUNTIFS('Daily entry'!$A$2:$A$3001,D$4,'Daily entry'!$B$2:$B$3001,$A5)>0,"✓","✗") -> ✗ | E5: =IF(COUNTIFS('Daily entry'!$A$2:$A$3001,E$4,'Daily entry'!$B$2:$B$3001,$A5)>0,"✓","✗") -> ✗ | F5: =IF(COUNTIFS('Daily entry'!$A$2:$A$3001,F$4,'Daily entry'!$B$2:$B$3001,$A5)>0,"✓","✗") -> ✗ | G5: =IF(COUNTIFS('Daily entry'!$A$2:$A$3001,G$4,'Daily entry'!$B$2:$B$3001,$A5)>0,"✓","✗") -> ✗ | H5: =IF(COUNTIFS('Daily entry'!$A$2:$A$3001,H$4,'Daily entry'!$B$2:$B$3001,$A5)>0,"✓","✗") -> ✗ | I5: =IF(COUNTIFS('Daily entry'!$A$2:$A$3001,I$4,'Daily entry'!$B$2:$B$3001,$A5)>0,"✓","✗") -> ✗ | J5: =IF(COUNTIFS('Daily entry'!$A$2:$A$3001,J$4,'Daily entry'!$B$2:$B$3001,$A5)>0,"✓","✗") -> ✗ | K5: =IF(COUNTIFS('Daily entry'!$A$2:$A$3001,K$4,'Daily entry'!$B$2:$B$3001,$A5)>0,"✓","✗") -> ✗ | ... Q5: =IF(COUNTIFS('Daily entry'!$A$2:$A$3001,Q$4,'Daily entry'!$B$2:$B$3001,$A5)>0,"✓","✗") -> ✗
A6: Juba International Airport | B6: =COUNTIF(D11:Q11,"✓") -> 8 | C6: =IF(COUNTIF('Daily entry'!$B$2:$B$3001,$A11)=0,"Never",_xlfn.MAXIFS('Daily entry'!$A$2:$A$3001,'Daily entry'!$B$2:$B$3001,$A11)) -> 46303 | D6: =IF(COUNTIFS('Daily entry'!$A$2:$A$3001,D$4,'Daily entry'!$B$2:$B$3001,$A6)>0,"✓","✗") -> ✗ | E6: =IF(COUNTIFS('Daily entry'!$A$2:$A$3001,E$4,'Daily entry'!$B$2:$B$3001,$A6)>0,"✓","✗") -> ✗ | F6: =IF(COUNTIFS('Daily entry'!$A$2:$A$3001,F$4,'Daily entry'!$B$2:$B$3001,$A6)>0,"✓","✗") -> ✗ | G6: =IF(COUNTIFS('Daily entry'!$A$2:$A$3001,G$4,'Daily entry'!$B$2:$B$3001,$A6)>0,"✓","✗") -> ✗ | H6: =IF(COUNTIFS('Daily entry'!$A$2:$A$3001,H$4,'Daily entry'!$B$2:$B$3001,$A6)>0,"✓","✗") -> ✗ | I6: =IF(COUNTIFS('Daily entry'!$A$2:$A$3001,I$4,'Daily entry'!$B$2:$B$3001,$A6)>0,"✓","✗") -> ✗ | J6: =IF(COUNTIFS('Daily entry'!$A$2:$A$3001,J$4,'Daily entry'!$B$2:$B$3001,$A6)>0,"✓","✗") -> ✗ | K6: =IF(COUNTIFS('Daily entry'!$A$2:$A$3001,K$4,'Daily entry'!$B$2:$B$3001,$A6)>0,"✓","✗") -> ✗ | ... Q6: =IF(COUNTIFS('Daily entry'!$A$2:$A$3001,Q$4,'Daily entry'!$B$2:$B$3001,$A6)>0,"✓","✗") -> ✗
A7: Litoba | B7: =COUNTIF(D12:Q12,"✓") -> 8 | C7: =IF(COUNTIF('Daily entry'!$B$2:$B$3001,$A12)=0,"Never",_xlfn.MAXIFS('Daily entry'!$A$2:$A$3001,'Daily entry'!$B$2:$B$3001,$A12)) -> 46303 | D7: =IF(COUNTIFS('Daily entry'!$A$2:$A$3001,D$4,'Daily entry'!$B$2:$B$3001,$A7)>0,"✓","✗") -> ✗ | E7: =IF(COUNTIFS('Daily entry'!$A$2:$A$3001,E$4,'Daily entry'!$B$2:$B$3001,$A7)>0,"✓","✗") -> ✗ | F7: =IF(COUNTIFS('Daily entry'!$A$2:$A$3001,F$4,'Daily entry'!$B$2:$B$3001,$A7)>0,"✓","✗") -> ✗ | G7: =IF(COUNTIFS('Daily entry'!$A$2:$A$3001,G$4,'Daily entry'!$B$2:$B$3001,$A7)>0,"✓","✗") -> ✗ | H7: =IF(COUNTIFS('Daily entry'!$A$2:$A$3001,H$4,'Daily entry'!$B$2:$B$3001,$A7)>0,"✓","✗") -> ✗ | I7: =IF(COUNTIFS('Daily entry'!$A$2:$A$3001,I$4,'Daily entry'!$B$2:$B$3001,$A7)>0,"✓","✗") -> ✗ | J7: =IF(COUNTIFS('Daily entry'!$A$2:$A$3001,J$4,'Daily entry'!$B$2:$B$3001,$A7)>0,"✓","✗") -> ✗ | K7: =IF(COUNTIFS('Daily entry'!$A$2:$A$3001,K$4,'Daily entry'!$B$2:$B$3001,$A7)>0,"✓","✗") -> ✗ | ... Q7: =IF(COUNTIFS('Daily entry'!$A$2:$A$3001,Q$4,'Daily entry'!$B$2:$B$3001,$A7)>0,"✓","✗") -> ✗
A8: Abaya | B8: =COUNTIF(D13:Q13,"✓") -> 8 | C8: =IF(COUNTIF('Daily entry'!$B$2:$B$3001,$A13)=0,"Never",_xlfn.MAXIFS('Daily entry'!$A$2:$A$3001,'Daily entry'!$B$2:$B$3001,$A13)) -> 46303 | D8: =IF(COUNTIFS('Daily entry'!$A$2:$A$3001,D$4,'Daily entry'!$B$2:$B$3001,$A8)>0,"✓","✗") -> ✗ | E8: =IF(COUNTIFS('Daily entry'!$A$2:$A$3001,E$4,'Daily entry'!$B$2:$B$3001,$A8)>0,"✓","✗") -> ✗ | F8: =IF(COUNTIFS('Daily entry'!$A$2:$A$3001,F$4,'Daily entry'!$B$2:$B$3001,$A8)>0,"✓","✗") -> ✗ | G8: =IF(COUNTIFS('Daily entry'!$A$2:$A$3001,G$4,'Daily entry'!$B$2:$B$3001,$A8)>0,"✓","✗") -> ✗ | H8: =IF(COUNTIFS('Daily entry'!$A$2:$A$3001,H$4,'Daily entry'!$B$2:$B$3001,$A8)>0,"✓","✗") -> ✗ | I8: =IF(COUNTIFS('Daily entry'!$A$2:$A$3001,I$4,'Daily entry'!$B$2:$B$3001,$A8)>0,"✓","✗") -> ✗ | J8: =IF(COUNTIFS('Daily entry'!$A$2:$A$3001,J$4,'Daily entry'!$B$2:$B$3001,$A8)>0,"✓","✗") -> ✗ | K8: =IF(COUNTIFS('Daily entry'!$A$2:$A$3001,K$4,'Daily entry'!$B$2:$B$3001,$A8)>0,"✓","✗") -> ✗ | ... Q8: =IF(COUNTIFS('Daily entry'!$A$2:$A$3001,Q$4,'Daily entry'!$B$2:$B$3001,$A8)>0,"✓","✗") -> ✗
A9: Jalle | B9: =COUNTIF(D14:Q14,"✓") -> 0 | C9: =IF(COUNTIF('Daily entry'!$B$2:$B$3001,$A14)=0,"Never",_xlfn.MAXIFS('Daily entry'!$A$2:$A$3001,'Daily entry'!$B$2:$B$3001,$A14)) -> Never | D9: =IF(COUNTIFS('Daily entry'!$A$2:$A$3001,D$4,'Daily entry'!$B$2:$B$3001,$A9)>0,"✓","✗") -> ✗ | E9: =IF(COUNTIFS('Daily entry'!$A$2:$A$3001,E$4,'Daily entry'!$B$2:$B$3001,$A9)>0,"✓","✗") -> ✗ | F9: =IF(COUNTIFS('Daily entry'!$A$2:$A$3001,F$4,'Daily entry'!$B$2:$B$3001,$A9)>0,"✓","✗") -> ✗ | G9: =IF(COUNTIFS('Daily entry'!$A$2:$A$3001,G$4,'Daily entry'!$B$2:$B$3001,$A9)>0,"✓","✗") -> ✗ | H9: =IF(COUNTIFS('Daily entry'!$A$2:$A$3001,H$4,'Daily entry'!$B$2:$B$3001,$A9)>0,"✓","✗") -> ✗ | I9: =IF(COUNTIFS('Daily entry'!$A$2:$A$3001,I$4,'Daily entry'!$B$2:$B$3001,$A9)>0,"✓","✗") -> ✗ | J9: =IF(COUNTIFS('Daily entry'!$A$2:$A$3001,J$4,'Daily entry'!$B$2:$B$3001,$A9)>0,"✓","✗") -> ✗ | K9: =IF(COUNTIFS('Daily entry'!$A$2:$A$3001,K$4,'Daily entry'!$B$2:$B$3001,$A9)>0,"✓","✗") -> ✗ | ... Q9: =IF(COUNTIFS('Daily entry'!$A$2:$A$3001,Q$4,'Daily entry'!$B$2:$B$3001,$A9)>0,"✓","✗") -> ✗
A10: Kerwa | B10: =COUNTIF(D15:Q15,"✓") -> 0 | C10: =IF(COUNTIF('Daily entry'!$B$2:$B$3001,$A15)=0,"Never",_xlfn.MAXIFS('Daily entry'!$A$2:$A$3001,'Daily entry'!$B$2:$B$3001,$A15)) -> Never | D10: =IF(COUNTIFS('Daily entry'!$A$2:$A$3001,D$4,'Daily entry'!$B$2:$B$3001,$A10)>0,"✓","✗") -> ✗ | E10: =IF(COUNTIFS('Daily entry'!$A$2:$A$3001,E$4,'Daily entry'!$B$2:$B$3001,$A10)>0,"✓","✗") -> ✗ | F10: =IF(COUNTIFS('Daily entry'!$A$2:$A$3001,F$4,'Daily entry'!$B$2:$B$3001,$A10)>0,"✓","✗") -> ✗ | G10: =IF(COUNTIFS('Daily entry'!$A$2:$A$3001,G$4,'Daily entry'!$B$2:$B$3001,$A10)>0,"✓","✗") -> ✗ | H10: =IF(COUNTIFS('Daily entry'!$A$2:$A$3001,H$4,'Daily entry'!$B$2:$B$3001,$A10)>0,"✓","✗") -> ✗ | I10: =IF(COUNTIFS('Daily entry'!$A$2:$A$3001,I$4,'Daily entry'!$B$2:$B$3001,$A10)>0,"✓","✗") -> ✗ | J10: =IF(COUNTIFS('Daily entry'!$A$2:$A$3001,J$4,'Daily entry'!$B$2:$B$3001,$A10)>0,"✓","✗") -> ✗ | K10: =IF(COUNTIFS('Daily entry'!$A$2:$A$3001,K$4,'Daily entry'!$B$2:$B$3001,$A10)>0,"✓","✗") -> ✗ | ... Q10: =IF(COUNTIFS('Daily entry'!$A$2:$A$3001,Q$4,'Daily entry'!$B$2:$B$3001,$A10)>0,"✓","✗") -> ✗
A11: Nimule | B11: =COUNTIF(D16:Q16,"✓") -> 0 | C11: =IF(COUNTIF('Daily entry'!$B$2:$B$3001,$A16)=0,"Never",_xlfn.MAXIFS('Daily entry'!$A$2:$A$3001,'Daily entry'!$B$2:$B$3001,$A16)) -> Never | D11: =IF(COUNTIFS('Daily entry'!$A$2:$A$3001,D$4,'Daily entry'!$B$2:$B$3001,$A11)>0,"✓","✗") -> ✗ | E11: =IF(COUNTIFS('Daily entry'!$A$2:$A$3001,E$4,'Daily entry'!$B$2:$B$3001,$A11)>0,"✓","✗") -> ✗ | F11: =IF(COUNTIFS('Daily entry'!$A$2:$A$3001,F$4,'Daily entry'!$B$2:$B$3001,$A11)>0,"✓","✗") -> ✓ | G11: =IF(COUNTIFS('Daily entry'!$A$2:$A$3001,G$4,'Daily entry'!$B$2:$B$3001,$A11)>0,"✓","✗") -> ✓ | H11: =IF(COUNTIFS('Daily entry'!$A$2:$A$3001,H$4,'Daily entry'!$B$2:$B$3001,$A11)>0,"✓","✗") -> ✓ | I11: =IF(COUNTIFS('Daily entry'!$A$2:$A$3001,I$4,'Daily entry'!$B$2:$B$3001,$A11)>0,"✓","✗") -> ✓ | J11: =IF(COUNTIFS('Daily entry'!$A$2:$A$3001,J$4,'Daily entry'!$B$2:$B$3001,$A11)>0,"✓","✗") -> ✓ | K11: =IF(COUNTIFS('Daily entry'!$A$2:$A$3001,K$4,'Daily entry'!$B$2:$B$3001,$A11)>0,"✓","✗") -> ✓ | ... Q11: =IF(COUNTIFS('Daily entry'!$A$2:$A$3001,Q$4,'Daily entry'!$B$2:$B$3001,$A11)>0,"✓","✗") -> ✗
A12: Rei-river port | B12: =COUNTIF(D17:Q17,"✓") -> 8 | C12: =IF(COUNTIF('Daily entry'!$B$2:$B$3001,$A17)=0,"Never",_xlfn.MAXIFS('Daily entry'!$A$2:$A$3001,'Daily entry'!$B$2:$B$3001,$A17)) -> 46303 | D12: =IF(COUNTIFS('Daily entry'!$A$2:$A$3001,D$4,'Daily entry'!$B$2:$B$3001,$A12)>0,"✓","✗") -> ✗ | E12: =IF(COUNTIFS('Daily entry'!$A$2:$A$3001,E$4,'Daily entry'!$B$2:$B$3001,$A12)>0,"✓","✗") -> ✗ | F12: =IF(COUNTIFS('Daily entry'!$A$2:$A$3001,F$4,'Daily entry'!$B$2:$B$3001,$A12)>0,"✓","✗") -> ✓ | G12: =IF(COUNTIFS('Daily entry'!$A$2:$A$3001,G$4,'Daily entry'!$B$2:$B$3001,$A12)>0,"✓","✗") -> ✓ | H12: =IF(COUNTIFS('Daily entry'!$A$2:$A$3001,H$4,'Daily entry'!$B$2:$B$3001,$A12)>0,"✓","✗") -> ✓ | I12: =IF(COUNTIFS('Daily entry'!$A$2:$A$3001,I$4,'Daily entry'!$B$2:$B$3001,$A12)>0,"✓","✗") -> ✓ | J12: =IF(COUNTIFS('Daily entry'!$A$2:$A$3001,J$4,'Daily entry'!$B$2:$B$3001,$A12)>0,"✓","✗") -> ✓ | K12: =IF(COUNTIFS('Daily entry'!$A$2:$A$3001,K$4,'Daily entry'!$B$2:$B$3001,$A12)>0,"✓","✗") -> ✓ | ... Q12: =IF(COUNTIFS('Daily entry'!$A$2:$A$3001,Q$4,'Daily entry'!$B$2:$B$3001,$A12)>0,"✓","✗") -> ✗
A13: Olikwi | B13: =COUNTIF(D18:Q18,"✓") -> 0 | C13: =IF(COUNTIF('Daily entry'!$B$2:$B$3001,$A18)=0,"Never",_xlfn.MAXIFS('Daily entry'!$A$2:$A$3001,'Daily entry'!$B$2:$B$3001,$A18)) -> Never | D13: =IF(COUNTIFS('Daily entry'!$A$2:$A$3001,D$4,'Daily entry'!$B$2:$B$3001,$A13)>0,"✓","✗") -> ✗ | E13: =IF(COUNTIFS('Daily entry'!$A$2:$A$3001,E$4,'Daily entry'!$B$2:$B$3001,$A13)>0,"✓","✗") -> ✗ | F13: =IF(COUNTIFS('Daily entry'!$A$2:$A$3001,F$4,'Daily entry'!$B$2:$B$3001,$A13)>0,"✓","✗") -> ✓ | G13: =IF(COUNTIFS('Daily entry'!$A$2:$A$3001,G$4,'Daily entry'!$B$2:$B$3001,$A13)>0,"✓","✗") -> ✓ | H13: =IF(COUNTIFS('Daily entry'!$A$2:$A$3001,H$4,'Daily entry'!$B$2:$B$3001,$A13)>0,"✓","✗") -> ✓ | I13: =IF(COUNTIFS('Daily entry'!$A$2:$A$3001,I$4,'Daily entry'!$B$2:$B$3001,$A13)>0,"✓","✗") -> ✓ | J13: =IF(COUNTIFS('Daily entry'!$A$2:$A$3001,J$4,'Daily entry'!$B$2:$B$3001,$A13)>0,"✓","✗") -> ✓ | K13: =IF(COUNTIFS('Daily entry'!$A$2:$A$3001,K$4,'Daily entry'!$B$2:$B$3001,$A13)>0,"✓","✗") -> ✓ | ... Q13: =IF(COUNTIFS('Daily entry'!$A$2:$A$3001,Q$4,'Daily entry'!$B$2:$B$3001,$A13)>0,"✓","✗") -> ✗
A14: Pogee | B14: =COUNTIF(D19:Q19,"✓") -> 0 | C14: =IF(COUNTIF('Daily entry'!$B$2:$B$3001,$A19)=0,"Never",_xlfn.MAXIFS('Daily entry'!$A$2:$A$3001,'Daily entry'!$B$2:$B$3001,$A19)) -> Never | D14: =IF(COUNTIFS('Daily entry'!$A$2:$A$3001,D$4,'Daily entry'!$B$2:$B$3001,$A14)>0,"✓","✗") -> ✗ | E14: =IF(COUNTIFS('Daily entry'!$A$2:$A$3001,E$4,'Daily entry'!$B$2:$B$3001,$A14)>0,"✓","✗") -> ✗ | F14: =IF(COUNTIFS('Daily entry'!$A$2:$A$3001,F$4,'Daily entry'!$B$2:$B$3001,$A14)>0,"✓","✗") -> ✗ | G14: =IF(COUNTIFS('Daily entry'!$A$2:$A$3001,G$4,'Daily entry'!$B$2:$B$3001,$A14)>0,"✓","✗") -> ✗ | H14: =IF(COUNTIFS('Daily entry'!$A$2:$A$3001,H$4,'Daily entry'!$B$2:$B$3001,$A14)>0,"✓","✗") -> ✗ | I14: =IF(COUNTIFS('Daily entry'!$A$2:$A$3001,I$4,'Daily entry'!$B$2:$B$3001,$A14)>0,"✓","✗") -> ✗ | J14: =IF(COUNTIFS('Daily entry'!$A$2:$A$3001,J$4,'Daily entry'!$B$2:$B$3001,$A14)>0,"✓","✗") -> ✗ | K14: =IF(COUNTIFS('Daily entry'!$A$2:$A$3001,K$4,'Daily entry'!$B$2:$B$3001,$A14)>0,"✓","✗") -> ✗ | ... Q14: =IF(COUNTIFS('Daily entry'!$A$2:$A$3001,Q$4,'Daily entry'!$B$2:$B$3001,$A14)>0,"✓","✗") -> ✗
A15: Lobone | B15: =COUNTIF(D20:Q20,"✓") -> 0 | C15: =IF(COUNTIF('Daily entry'!$B$2:$B$3001,$A20)=0,"Never",_xlfn.MAXIFS('Daily entry'!$A$2:$A$3001,'Daily entry'!$B$2:$B$3001,$A20)) -> Never | D15: =IF(COUNTIFS('Daily entry'!$A$2:$A$3001,D$4,'Daily entry'!$B$2:$B$3001,$A15)>0,"✓","✗") -> ✗ | E15: =IF(COUNTIFS('Daily entry'!$A$2:$A$3001,E$4,'Daily entry'!$B$2:$B$3001,$A15)>0,"✓","✗") -> ✗ | F15: =IF(COUNTIFS('Daily entry'!$A$2:$A$3001,F$4,'Daily entry'!$B$2:$B$3001,$A15)>0,"✓","✗") -> ✗ | G15: =IF(COUNTIFS('Daily entry'!$A$2:$A$3001,G$4,'Daily entry'!$B$2:$B$3001,$A15)>0,"✓","✗") -> ✗ | H15: =IF(COUNTIFS('Daily entry'!$A$2:$A$3001,H$4,'Daily entry'!$B$2:$B$3001,$A15)>0,"✓","✗") -> ✗ | I15: =IF(COUNTIFS('Daily entry'!$A$2:$A$3001,I$4,'Daily entry'!$B$2:$B$3001,$A15)>0,"✓","✗") -> ✗ | J15: =IF(COUNTIFS('Daily entry'!$A$2:$A$3001,J$4,'Daily entry'!$B$2:$B$3001,$A15)>0,"✓","✗") -> ✗ | K15: =IF(COUNTIFS('Daily entry'!$A$2:$A$3001,K$4,'Daily entry'!$B$2:$B$3001,$A15)>0,"✓","✗") -> ✗ | ... Q15: =IF(COUNTIFS('Daily entry'!$A$2:$A$3001,Q$4,'Daily entry'!$B$2:$B$3001,$A15)>0,"✓","✗") -> ✗
A16: Rasul (Landili) | B16: =COUNTIF(D21:Q21,"✓") -> 0 | C16: =IF(COUNTIF('Daily entry'!$B$2:$B$3001,$A21)=0,"Never",_xlfn.MAXIFS('Daily entry'!$A$2:$A$3001,'Daily entry'!$B$2:$B$3001,$A21)) -> Never | D16: =IF(COUNTIFS('Daily entry'!$A$2:$A$3001,D$4,'Daily entry'!$B$2:$B$3001,$A16)>0,"✓","✗") -> ✗ | E16: =IF(COUNTIFS('Daily entry'!$A$2:$A$3001,E$4,'Daily entry'!$B$2:$B$3001,$A16)>0,"✓","✗") -> ✗ | F16: =IF(COUNTIFS('Daily entry'!$A$2:$A$3001,F$4,'Daily entry'!$B$2:$B$3001,$A16)>0,"✓","✗") -> ✗ | G16: =IF(COUNTIFS('Daily entry'!$A$2:$A$3001,G$4,'Daily entry'!$B$2:$B$3001,$A16)>0,"✓","✗") -> ✗ | H16: =IF(COUNTIFS('Daily entry'!$A$2:$A$3001,H$4,'Daily entry'!$B$2:$B$3001,$A16)>0,"✓","✗") -> ✗ | I16: =IF(COUNTIFS('Daily entry'!$A$2:$A$3001,I$4,'Daily entry'!$B$2:$B$3001,$A16)>0,"✓","✗") -> ✗ | J16: =IF(COUNTIFS('Daily entry'!$A$2:$A$3001,J$4,'Daily entry'!$B$2:$B$3001,$A16)>0,"✓","✗") -> ✗ | K16: =IF(COUNTIFS('Daily entry'!$A$2:$A$3001,K$4,'Daily entry'!$B$2:$B$3001,$A16)>0,"✓","✗") -> ✗ | ... Q16: =IF(COUNTIFS('Daily entry'!$A$2:$A$3001,Q$4,'Daily entry'!$B$2:$B$3001,$A16)>0,"✓","✗") -> ✗
... A43: Budi Airstrip | B43: =COUNTIF(D48:Q48,"✓") -> 0 | C43: =IF(COUNTIF('Daily entry'!$B$2:$B$3001,$A48)=0,"Never",_xlfn.MAXIFS('Daily entry'!$A$2:$A$3001,'Daily entry'!$B$2:$B$3001,$A48)) -> Never | D43: =IF(COUNTIFS('Daily entry'!$A$2:$A$3001,D$4,'Daily entry'!$B$2:$B$3001,$A43)>0,"✓","✗") -> ✗ | E43: =IF(COUNTIFS('Daily entry'!$A$2:$A$3001,E$4,'Daily entry'!$B$2:$B$3001,$A43)>0,"✓","✗") -> ✗ | F43: =IF(COUNTIFS('Daily entry'!$A$2:$A$3001,F$4,'Daily entry'!$B$2:$B$3001,$A43)>0,"✓","✗") -> ✗ | G43: =IF(COUNTIFS('Daily entry'!$A$2:$A$3001,G$4,'Daily entry'!$B$2:$B$3001,$A43)>0,"✓","✗") -> ✗ | H43: =IF(COUNTIFS('Daily entry'!$A$2:$A$3001,H$4,'Daily entry'!$B$2:$B$3001,$A43)>0,"✓","✗") -> ✗ | I43: =IF(COUNTIFS('Daily entry'!$A$2:$A$3001,I$4,'Daily entry'!$B$2:$B$3001,$A43)>0,"✓","✗") -> ✗ | J43: =IF(COUNTIFS('Daily entry'!$A$2:$A$3001,J$4,'Daily entry'!$B$2:$B$3001,$A43)>0,"✓","✗") -> ✗ | K43: =IF(COUNTIFS('Daily entry'!$A$2:$A$3001,K$4,'Daily entry'!$B$2:$B$3001,$A43)>0,"✓","✗") -> ✗ | ... Q43: =IF(COUNTIFS('Daily entry'!$A$2:$A$3001,Q$4,'Daily entry'!$B$2:$B$3001,$A43)>0,"✓","✗") -> ✗
D44: 0 | E44: 0 | F44: 0 | G44: 0 | H44: 0 | I44: 0 | J44: 0 | K44: 0 | L44: 0 | M44: 0 | N44: 0 | O44: 0 | P44: 0 | Q44: 0

Sheet wide_data_OLD
A1: date | B1: main_ground_crossing_nimule_screened_total | C1: main_ground_crossing_nimule_alerts_triggered | D1: main_ground_crossing_nimule_alerts_discarded | E1: kaya_po_e_screened_total | F1: kaya_po_e_alerts_triggered | G1: kaya_po_e_alerts_discarded | H1: olikwi_po_e_nimule_screened_total | I1: olikwi_po_e_nimule_alerts_triggered | J1: olikwi_po_e_nimule_alerts_discarded | K1: rei_river_port_screened_total | L1: rei_river_port_alerts_triggered | M1: rei_river_port_alerts_discarded | N1: Juba_International _Airport_screened_total | O1: Juba_International _Airport_alerts_triggered | P1: Juba_International _Airport_alerts_discarded | Q1: Nabanga_land_crossing_screened_total | R1: Nabanga_land_crossing_alerts_triggered | S1: Nabanga_land_crossing_alerts_discarded | T1: Litoba_land_crossing_screened_total | U1: Litoba_land_crossing_alerts_triggered | V1: Litoba_land_crossing_alerts_discarded | W1: Abaya_land_crossing_screened_total | X1: Abaya_land_crossing_alerts_triggered | Y1: Abaya_land_crossing_alerts_discarded | Z1: Jalle_land_crossing_screened_total | AA1: Jalle_land_crossing_alerts_triggered | AB1: Jalle_land_crossing_alerts_discarded | AC1: Kerwa_land_crossing_screened_total | AD1: Kerwa_land_crossing_alerts_triggered | AE1: Kerwa_land_crossing_alerts_discarded | AF1: Pogee_land_crossing_screened_total | AG1: Pogee_land_crossing_alerts_triggered | AH1: Pogee_land_crossing_alerts_discarded | AI1: Lobone_land_crossing_screened_total | AJ1: Lobone_land_crossing_alerts_triggered | AK1: Lobone_land_crossing_alerts_discarded | AL1: Rasul (Landili)_land_crossing_screened_total | AM1: Rasul (Landili)_land_crossing_alerts_triggered | AN1: Rasul (Landili)_land_crossing_alerts_discarded | AO1: Kaya_land_crossing_screened_total | AP1: Kaya_land_crossing_alerts_triggered | AQ1: Kaya_land_crossing_alerts_discarded | AR1: Saliamusala_land_crossing_screened_total | AS1: Saliamusala_land_crossing_alerts_triggered | AT1: Saliamusala_land_crossing_alerts_discarded | AU1: Khor Kaya_land_crossing_screened_total | AV1: Khor Kaya_land_crossing_alerts_triggered | AW1: Khor Kaya_land_crossing_alerts_discarded | AX1: Bazi_land_crossing_screened_total | AY1: Bazi_land_crossing_alerts_triggered | AZ1: Bazi_land_crossing_alerts_discarded | BA1: Ukaba/Okaba_land_crossing_screened_total | BB1: Ukaba/Okaba_land_crossing_alerts_triggered | BC1: Ukaba/Okaba_land_crossing_alerts_discarded | BD1: Sangua-1_land_crossing_screened_total | BE1: Sangua-1_land_crossing_alerts_triggered | BF1: Sangua-1_land_crossing_alerts_discarded | BG1: South Yubu_land_crossing_screened_total | BH1: South Yubu_land_crossing_alerts_triggered | BI1: South Yubu_land_crossing_alerts_discarded | BJ1: Nangarangara_land_crossing_screened_total | BK1: Nangarangara_land_crossing_alerts_triggered | BL1: Nangarangara_land_crossing_alerts_discarded | BM1: Nabiapai-Yambio_land_crossing_screened_total | BN1: Nabiapai-Yambio_land_crossing_alerts_triggered | BO1: Nabiapai-Yambio_land_crossing_alerts_discarded | BP1: Yambio_Airport_screened_total | BQ1: Yambio_Airport_alerts_triggered | BR1: Yambio_Airport_alerts_discarded | BS1: Sakure_land_crossing_screened_total | BT1: Sakure_land_crossing_alerts_triggered | BU1: Sakure_land_crossing_alerts_discarded | BV1: Ombasi_land_crossing_screened_total | BW1: Ombasi_land_crossing_alerts_triggered | BX1: Ombasi_land_crossing_alerts_discarded | BY1: Minyori_land_crossing_screened_total | BZ1: Minyori_land_crossing_alerts_triggered | CA1: Minyori_land_crossing_alerts_discarded | CB1: Garamba_land_crossing_screened_total | CC1: Garamba_land_crossing_alerts_triggered | CD1: Garamba_land_crossing_alerts_discarded | CE1: Yei_Airport_screened_total | CF1: Yei_Airport_alerts_triggered | CG1: Yei_Airport_alerts_discarded | CH1: Lasu-Libogo_land_crossing_screened_total | CI1: Lasu-Libogo_land_crossing_alerts_triggered | CJ1: Lasu-Libogo_land_crossing_alerts_discarded | CK1: Bazikangbi_land_crossing_screened_total | CL1: Bazikangbi_land_crossing_alerts_triggered | CM1: Bazikangbi_land_crossing_alerts_discarded | CN1: Nabiapai-Ezo_land_crossing_screened_total | CO1: Nabiapai-Ezo_land_crossing_alerts_triggered | CP1: Nabiapai-Ezo_land_crossing_alerts_discarded | CQ1: Wau_Airport_screened_total | CR1: Wau_Airport_alerts_triggered | CS1: Wau_Airport_alerts_discarded | CT1: Sertenya_land_crossing_screened_total | CU1: Sertenya_land_crossing_alerts_triggered | CV1: Sertenya_land_crossing_alerts_discarded | CW1: Bira_land_crossing_screened_total | CX1: Bira_land_crossing_alerts_triggered | CY1: Bira_land_crossing_alerts_discarded | CZ1: Katire_land_crossing_screened_total | DA1: Katire_land_crossing_alerts_triggered | DB1: Katire_land_crossing_alerts_discarded | DC1: Lofus_land_crossing_screened_total | DD1: Lofus_land_crossing_alerts_triggered | DE1: Lofus_land_crossing_alerts_discarded | DF1: Nadapal_land_crossing_screened_total | DG1: Nadapal_land_crossing_alerts_triggered | DH1: Nadapal_land_crossing_alerts_discarded | DI1: Torit_Airstrip_screened_total | DJ1: Torit_Airstrip_alerts_triggered | DK1: Torit_Airstrip_alerts_discarded | DL1: Budi_Airstrip_screened_total | DM1: Budi_Airstrip_alerts_triggered | DN1: Budi_Airstrip_alerts_discarded
A2: 46180 | B2: 10496 | C2: 1 | D2: 1 | E2: 2147 | F2: 0 | G2: 0
A3: 46181 | B3: 12584 | C3: 0 | D3: 0 | E3: 1921 | F3: 0 | G3: 0
A4: 46182 | B4: 12288 | C4: 0 | D4: 0 | E4: 2067 | F4: 0 | G4: 0
A5: 46183 | B5: 13727 | C5: 0 | D5: 0 | E5: 2424 | F5: 0 | G5: 0
A6: 46184 | B6: 13974 | C6: 0 | D6: 0 | E6: 2004 | F6: 0 | G6: 0
A7: 46185 | B7: 13868 | C7: 0 | D7: 0 | E7: 2122 | F7: 0 | G7: 0 | K7: 137 | L7: 0 | M7: 0
A8: 46186 | B8: 10147 | C8: 0 | D8: 0 | E8: 1544 | F8: 0 | G8: 0 | H8: 801 | I8: 1 | J8: 1 | K8: 172 | L8: 0 | M8: 0
A9: 46187 | B9: 14258 | C9: 0 | D9: 0 | E9: 1995 | F9: 0 | G9: 0 | H9: 522 | I9: 0 | J9: 0 | K9: 234 | L9: 0 | M9: 0
A10: 46188
A11: 46189 | B11: 14333 | C11: 0 | D11: 0 | E11: 2416 | F11: 0 | G11: 0 | H11: 857 | I11: 0 | J11: 0 | K11: 345 | L11: 0 | M11: 0
A12: 46190 | B12: 13066 | C12: 0 | D12: 0 | E12: 2140 | F12: 0 | G12: 0 | H12: 735 | I12: 0 | J12: 0 | K12: 389 | L12: 0 | M12: 0
A13: 46191
A14: 46192 | B14: 13939 | C14: 0 | D14: 0 | E14: 3000 | F14: 0 | G14: 0 | H14: 700 | I14: 1 | J14: 1 | K14: 371 | L14: 0 | M14: 0
A15: 46193 | B15: 14514 | C15: 0 | D15: 0 | E15: 3249 | F15: 0 | G15: 0 | H15: 705 | I15: 0 | J15: 0 | K15: 307 | L15: 0 | M15: 0
A16: 46194 | B16: 9907 | C16: 0 | D16: 0 | E16: 1981 | F16: 0 | G16: 0 | H16: 1045 | I16: 0 | J16: 0 | K16: 375 | L16: 0 | M16: 0
A17: 46195
A18: 46196 | B18: 15267 | C18: 0 | D18: 0 | E18: 3768 | F18: 0 | G18: 0 | H18: 1060 | I18: 0 | J18: 0 | K18: 346 | L18: 0 | M18: 0
A19: 46197
A20: 46198 | B20: 12656 | C20: 0 | D20: 0 | E20: 3555 | F20: 0 | G20: 0 | H20: 1339 | I20: 0 | J20: 0 | K20: 390 | L20: 0 | M20: 0
A21: 46199 | B21: 12166 | C21: 0 | D21: 0 | E21: 3670 | F21: 0 | G21: 0 | H21: 918 | I21: 0 | J21: 0 | K21: 420 | L21: 0 | M21: 0
A22: 46200 | B22: 13579 | C22: 0 | D22: 0 | E22: 2563 | F22: 0 | G22: 0 | H22: 1006 | I22: 0 | J22: 0 | K22: 385 | L22: 0 | M22: 0
A23: 46201
A24: 46202 | B24: 10529 | C24: 0 | D24: 0 | E24: 3443 | F24: 0 | G24: 0 | H24: 930 | I24: 0 | J24: 0 | K24: 404 | L24: 0 | M24: 0
A25: 46203 | B25: 12835 | C25: 0 | D25: 0 | E25: 3586 | F25: 0 | G25: 0 | H25: 1040 | I25: 0 | J25: 0 | K25: 408 | L25: 0 | M25: 0
A26: 46204
A27: 46205 | B27: 11537 | C27: 0 | D27: 0 | E27: 4093 | F27: 0 | G27: 0 | H27: 1132 | I27: 0 | J27: 0 | K27: 441 | L27: 0 | M27: 0
A28: 46206
A29: 46207
A30: 46208 | B30: 13009 | C30: 0 | D30: 0 | E30: 3662 | F30: 0 | G30: 0 | H30: 1860 | I30: 0 | J30: 0 | K30: 460 | L30: 0 | M30: 0
A31: 46209 | B31: 12584 | C31: 0 | D31: 0 | E31: 3053 | F31: 0 | G31: 0 | H31: 1860 | I31: 0 | J31: 0 | K31: 520 | L31: 0 | M31: 0
A32: 46210 | B32: 10274 | C32: 0 | D32: 0 | E32: 6249 | F32: 0 | G32: 0 | H32: 1386 | I32: 0 | J32: 0 | K32: 400 | L32: 0 | M32: 0
A33: 46211 | B33: 12793 | C33: 0 | D33: 0 | E33: 10109 | F33: 0 | G33: 0 | H33: 1332 | I33: 0 | J33: 0 | K33: 410 | L33: 0 | M33: 0
A34: 46212 | B34: 10771 | C34: 0 | D34: 0 | E34: 4175 | F34: 0 | G34: 0 | H34: 1240 | I34: 0 | J34: 0 | K34: 380 | L34: 0 | M34: 0
A35: 46213
A36: 46214
A37: 46215 | B37: 12134 | C37: 0 | D37: 0 | E37: 11143 | F37: 0 | G37: 0 | H37: 878 | I37: 0 | J37: 0 | K37: 463 | L37: 0 | M37: 0
A38: 46216
A39: 46217 | B39: 11188 | C39: 0 | D39: 0 | E39: 3366 | F39: 0 | G39: 0 | H39: 1160 | I39: 0 | J39: 0 | K39: 564 | L39: 0 | M39: 0
A40: 46218 | B40: 12295 | C40: 0 | D40: 0 | E40: 4164 | F40: 0 | G40: 0 | H40: 1120 | I40: 0 | J40: 0 | K40: 593 | L40: 0 | M40: 0
...
